Workbook

Sheet QA Overview
A1: Field | B1: Value
A2: Project Name | B2: Indotix
A3: Application Type | B3: Laravel monolith web app + Inertia React frontend + Sanctum/Mobile API; Flutter companion app detected in sibling folder.
A4: Framework | B4: PHP ^8.2; Laravel ^12.0; Fortify; Sanctum; Reverb; Spatie PDF
A5: Frontend | B5: Inertia React ^2.3.7; React ^19.2.0; TypeScript; Tailwind ^4.0.0; Radix UI; Vite
A6: Backend | B6: Laravel MVC/controllers/services/models/middleware with MySQL-compatible database configuration in .env.example.
A7: Database | B7: Configured through Laravel database layer; models include User, MitraWisataOnboarding, WisataTicket, WisataBooking, Voucher, PublicBanner, PublicPartner, PublicPartOfLogo, etc.
A8: QA Document Version | B8: 1.0
A9: Created Date | B9: 2026-08-25
A10: Prepared For | B10: Indotix QA Engineer / Project Stakeholders
A11: Testing Scope | B11: Manual QA, regression, smoke, access-control, security-oriented validation, compatibility, and API coverage based on current codebase routes/controllers/pages/tests.
A12: Testing Objective | B12: Validate tourism-first Indotix web/mobile API flows, admin/mitra/user roles, public content management, booking/payment/ticket scan, and retired module blocking before release.
A13: Total Laravel Routes Analyzed | B13: 632
A14: Total Test Scenarios | B14: =COUNTA('Test Scenarios'!$A$2:$A$500)
A15: Total Test Cases | B15: =COUNTA('Test Cases'!$A$2:$A$1000)
A16: P0 Test Cases | B16: =COUNTIF('Test Cases'!$M$2:$M$1000,"P0")
A17: P1 Test Cases | B17: =COUNTIF('Test Cases'!$M$2:$M$1000,"P1")
A18: P2 Test Cases | B18: =COUNTIF('Test Cases'!$M$2:$M$1000,"P2")
A19: P3 Test Cases | B19: =COUNTIF('Test Cases'!$M$2:$M$1000,"P3")
A20: Passed | B20: =COUNTIF('Test Cases'!$L$2:$L$1000,"Passed")
A21: Failed | B21: =COUNTIF('Test Cases'!$L$2:$L$1000,"Failed")
A22: Blocked | B22: =COUNTIF('Test Cases'!$L$2:$L$1000,"Blocked")
A23: Not Run | B23: =COUNTIF('Test Cases'!$L$2:$L$1000,"Not Run")
A24: Retest | B24: =COUNTIF('Test Cases'!$L$2:$L$1000,"Retest")
A25: Executed | B25: =COUNTIFS('Test Cases'!$L$2:$L$1000,"<>Not Run",'Test Cases'!$L$2:$L$1000,"<>")
A26: Pass Rate | B26: =IFERROR(COUNTIF('Test Cases'!$L$2:$L$1000,"Passed")/COUNTIFS('Test Cases'!$L$2:$L$1000,"<>Not Run",'Test Cases'!$L$2:$L$1000,"<>"),0)
A27: Fail Rate | B27: =IFERROR(COUNTIF('Test Cases'!$L$2:$L$1000,"Failed")/COUNTIFS('Test Cases'!$L$2:$L$1000,"<>Not Run",'Test Cases'!$L$2:$L$1000,"<>"),0)
A28: Execution Progress | B28: =IFERROR(COUNTIFS('Test Cases'!$L$2:$L$1000,"<>Not Run",'Test Cases'!$L$2:$L$1000,"<>")/COUNTA('Test Cases'!$A$2:$A$1000),0)

Sheet Test Plan
A1: Section | B1: Description
A2: Testing Objective | B2: Confirm Indotix can be released with correct tourism-first public UX, reliable user booking/payment/ticket-scan flows, safe admin/mitra operations, and role-based access control.
A3: Testing Scope | B3: Web public pages, authenticated user flows, admin portal, mitra wisata portal, Sanctum mobile API, public content management, voucher, QR entry, e-ticket, notifications, profile, and regression of retired module blocking.
A4: In Scope | B4: Functional, validation, negative, boundary, UI/UX, responsive, security-oriented, access-control, integration/API, smoke, regression, data integrity, error handling, and compatibility tests.
A5: Out of Scope | B5: Production payment settlement, real WhatsApp/SMS/push delivery to customers, destructive production reset, penetration exploitation, and direct testing of hidden/retired business modules as active features.
A6: Testing Approach | B6: Risk-based testing: P0/P1 cover auth, booking, payment, QR scan, ownership, admin/mitra data changes, and content that affects public conversion; P2/P3 cover lower-risk UI and legacy verification.
A7: Testing Types | B7: Functional, UI, UX validation, negative, boundary, validation, authentication, authorization, security, integration, regression, smoke, compatibility, responsive, data integrity, error handling, and performance observation.
A8: Entry Criteria | B8: QA environment deployed, database seeded with guest/user/admin/mitra test accounts, at least one live wisata destination with tickets and voucher, mail/payment providers configured to sandbox/fake mode.
A9: Exit Criteria | B9: All P0 passed, no open Critical defects, no open High security/access-control defects, smoke suite passed, regression suite reviewed, release notes and known issues approved.
A10: Suspension Criteria | B10: Environment unavailable, schema/migration mismatch prevents core testing, test data cannot be created safely, payment sandbox unavailable for payment test cycle, or critical blocker prevents login.
A11: Resumption Criteria | B11: Environment restored, blocker fixed or workaround approved, test data reset/recreated, and failed cases retested.
A12: Test Environment | B12: Laravel 12 app on QA/staging, MySQL-compatible DB, storage linked, mail sandbox/fake, Midtrans sandbox/fake, Redis optional, web browsers and mobile viewport/devices listed in Compatibility Test sheet.
... A17: Smoke Testing Strategy | B17: Short deployment validation: home, catalog, detail, login, booking review, admin dashboard, admin wisata, mitra dashboard, mitra QR, discovery API, and retired route blocking.

Sheet Test Scenarios
A1: Scenario ID | B1: Module | C1: Feature | D1: Scenario | E1: Role | F1: Test Type | G1: Priority | H1: Risk Level | I1: Implementation Status | J1: Notes
A2: TS-ADMIN-CONTENT-001 | B2: Admin Public Content | C2: Homepage and Static Content Management | D2: Verify admin CRUD for public-facing content modules | E2: Admin | F2: Functional | G2: P1 | H2: High | I2: Implemented
A3: TS-ADMIN-MITRA-001 | B3: Admin Mitra Wisata | C3: Partner Management | D3: Verify admin management of wisata partners and documents | E3: Admin | F3: Access Control | G3: P1 | H3: High | I3: Implemented
A4: TS-ADMIN-SYSTEM-001 | B4: Admin System | C4: Users / Notifications / Settings / Reset | D4: Verify platform administration utilities | E4: Admin | F4: Functional | G4: P1 | H4: High | I4: Implemented
A5: TS-ADMIN-WISATA-001 | B5: Admin Wisata | C5: Destination / Ticket / Booking / Finance | D5: Verify admin operational wisata modules | E5: Admin | F5: Functional | G5: P0 | H5: Critical | I5: Implemented
A6: TS-API-001 | B6: Mobile API | C6: Auth / Discovery / Booking / Profile | D6: Verify Sanctum mobile API contract and protections | E6: Mobile User | F6: Integration | G6: P0 | H6: Critical | I6: Implemented
A7: TS-AUTH-001 | B7: Authentication | C7: Web Login | D7: Verify valid and invalid web login behavior including role redirect and rate limiting | E7: Guest/User/Admin/Mitra | F7: Authentication | G7: P0 | H7: Critical | I7: Implemented
A8: TS-AUTH-002 | B8: Authentication | C8: Registration | D8: Verify user registration requires profile identity, phone/WhatsApp, password, and legal acceptance | E8: Guest | F8: Validation | G8: P0 | H8: Critical | I8: Implemented
A9: TS-AUTH-003 | B9: Authentication | C9: Password Reset / Email Verification / 2FA | D9: Verify account recovery and verification flows are usable and protected | E9: Guest/User | F9: Authentication | G9: P1 | H9: High | I9: Implemented
A10: TS-CATALOG-001 | B10: Wisata Catalog | C10: Search and Listing | D10: Verify wisata listing, search, filter, empty state, and detail navigation | E10: Guest/User | F10: Functional | G10: P0 | H10: High | I10: Implemented
A11: TS-HOME-001 | B11: Public Home | C11: Homepage Rendering | D11: Verify homepage renders dynamic tourism-first content without retired product copy | E11: Guest/User | F11: UI | G11: P0 | H11: High | I11: Implemented
A12: TS-MITRA-001 | B12: Mitra Wisata | C12: Owned Destination and Operations | D12: Verify mitra can operate only owned wisata resources | E12: Mitra | F12: Access Control | G12: P0 | H12: Critical | I12: Implemented
A13: TS-RETIRE-001 | B13: Retired/Partial Modules | C13: Legacy Product Surface | D13: Verify retired legacy product modules remain blocked or marked partial | E13: Admin/Guest/Mitra | F13: Regression | G13: P2 | H13: Medium | I13: Partial | J13: Models/pages for hotel/event/academy/retail still exist, but middleware blocks active product surface.
A14: TS-SEC-001 | B14: Security | C14: Access Control and Input Abuse | D14: Verify defensive controls for common attack surface | E14: All Roles | F14: Security | G14: P0 | H14: Critical | I14: Implemented
A15: TS-USER-001 | B15: User Account | C15: Profile / Notifications / Reviews / Chat | D15: Verify authenticated user account features | E15: User | F15: Functional | G15: P1 | H15: Medium | I15: Implemented
A16: TS-WISATA-BOOKING-001 | B16: Wisata Booking | C16: Booking and Payment | D16: Verify wisata booking draft, checkout, voucher, payment, ticket delivery, and history | E16: User | F16: Functional | G16: P0 | H16: Critical | I16: Implemented
A17: TS-WISATA-DETAIL-001 | B17: Wisata Detail | C17: Destination Detail | D17: Verify public destination detail displays correct tourism data and ticket selection | E17: Guest/User | F17: Functional | G17: P0 | H17: High | I17: Implemented
A18: TS-WISATA-SCAN-001 | B18: Wisata Scan | C18: Ticket Usage Scan | D18: Verify user scans mitra QR and ticket can only be consumed once | E18: User/Mitra | F18: Access Control | G18: P0 | H18: Critical | I18: Implemented

Sheet Test Cases
A1: Test Case ID | B1: Scenario ID | C1: Module | D1: Feature | E1: Test Case Title | F1: Role | G1: Preconditions | H1: Test Data | I1: Test Steps | J1: Expected Result | K1: Actual Result | L1: Status | M1: Priority | N1: Severity | O1: Test Type | P1: Environment | Q1: Browser / Device | R1: Requirement / Route | S1: Automation Candidate | T1: Regression | U1: Created By | V1: Executed By | W1: Execution Date | X1: Bug ID | Y1: Notes
A2: TC-AUTH-001 | B2: TS-AUTH-001 | C2: Authentication | D2: Web Login | E2: Login with valid user credentials | F2: Guest | G2: Login page is reachable. | H2: Registered user email and valid password | I2: 1. Open /login. 2. Enter the test data. 3. Submit the login form. 4. Observe validation, redirect, and session state. | J2: User is authenticated and redirected to the correct user-facing page. | L2: Not Run | M2: P0 | N2: Critical | O2: Authentication | P2: Staging / QA | Q2: Chrome desktop + Android Chrome unless specified | R2: /login | S2: Maybe | T2: Yes | U2: Codex QA Generator
A3: TC-AUTH-002 | B3: TS-AUTH-001 | C3: Authentication | D3: Web Login | E3: Login rejects invalid password | F3: Guest | G3: Login page is reachable. | H3: Registered email with wrong password | I3: 1. Open /login. 2. Enter the test data. 3. Submit the login form. 4. Observe validation, redirect, and session state. | J3: Login fails, validation message is shown, and session is not authenticated. | L3: Not Run | M3: P0 | N3: High | O3: Negative | P3: Staging / QA | Q3: Chrome desktop + Android Chrome unless specified | R3: /login | S3: Maybe | T3: Yes | U3: Codex QA Generator
A4: TC-AUTH-003 | B4: TS-AUTH-001 | C4: Authentication | D4: Web Login | E4: Login rejects empty credentials | F4: Guest | G4: Login page is reachable. | H4: Blank email and password | I4: 1. Open /login. 2. Enter the test data. 3. Submit the login form. 4. Observe validation, redirect, and session state. | J4: Required field errors appear without creating an authenticated session. | L4: Not Run | M4: P1 | N4: High | O4: Validation | P4: Staging / QA | Q4: Chrome desktop + Android Chrome unless specified | R4: /login | S4: Maybe | T4: Yes | U4: Codex QA Generator
A5: TC-AUTH-004 | B5: TS-AUTH-001 | C5: Authentication | D5: Web Login | E5: Login rate limit is enforced | F5: Guest | G5: Login page is reachable. | H5: Repeated invalid attempts on same email/IP | I5: 1. Open /login. 2. Enter the test data. 3. Submit the login form. 4. Observe validation, redirect, and session state. | J5: Application throttles repeated attempts and shows a friendly rate-limit message. | L5: Not Run | M5: P1 | N5: High | O5: Security | P5: Staging / QA | Q5: Chrome desktop + Android Chrome unless specified | R5: /login | S5: Maybe | T5: Yes | U5: Codex QA Generator
A6: TC-AUTH-005 | B6: TS-AUTH-001 | C6: Authentication | D6: Web Login | E6: Password visibility toggle works | F6: Guest | G6: Login page is reachable. | H6: Any password value | I6: 1. Open /login. 2. Enter the test data. 3. Submit the login form. 4. Observe validation, redirect, and session state. | J6: Password field toggles between masked and visible without changing the value. | L6: Not Run | M6: P2 | N6: Low | O6: UI | P6: Staging / QA | Q6: Chrome desktop + Android Chrome unless specified | R6: /login | S6: Maybe | T6: Yes | U6: Codex QA Generator
A7: TC-AUTH-006 | B7: TS-AUTH-002 | C7: Authentication | D7: Registration | E7: Register with valid required fields | F7: Guest | G7: Register page is reachable. | H7: Name, email, phone/WhatsApp, password confirmation, legal checklist checked | I7: 1. Open /register. 2. Fill fields according to test data. 3. Submit registration. 4. Observe validation or success flow. | J7: Account is created, verification flow is started, and no password is exposed. | L7: Not Run | M7: P0 | N7: High | O7: Validation | P7: Staging / QA | Q7: Chrome desktop + Android Chrome unless specified | R7: /register | S7: Maybe | T7: Yes | U7: Codex QA Generator
A8: TC-AUTH-007 | B8: TS-AUTH-002 | C8: Authentication | D8: Registration | E8: Register rejects missing phone/WhatsApp | F8: Guest | G8: Register page is reachable. | H8: Valid identity without phone/WhatsApp | I8: 1. Open /register. 2. Fill fields according to test data. 3. Submit registration. 4. Observe validation or success flow. | J8: Registration fails with phone/WhatsApp required error. | L8: Not Run | M8: P0 | N8: High | O8: Validation | P8: Staging / QA | Q8: Chrome desktop + Android Chrome unless specified | R8: /register | S8: Maybe | T8: Yes | U8: Codex QA Generator
A9: TC-AUTH-008 | B9: TS-AUTH-002 | C9: Authentication | D9: Registration | E9: Register rejects unchecked legal terms | F9: Guest | G9: Register page is reachable. | H9: Valid identity with legal checklist unchecked | I9: 1. Open /register. 2. Fill fields according to test data. 3. Submit registration. 4. Observe validation or success flow. | J9: Modal/validation asks user to accept terms and account is not created. | L9: Not Run | M9: P0 | N9: High | O9: Validation | P9: Staging / QA | Q9: Chrome desktop + Android Chrome unless specified | R9: /register | S9: Maybe | T9: Yes | U9: Codex QA Generator
A10: TC-AUTH-009 | B10: TS-AUTH-002 | C10: Authentication | D10: Registration | E10: Register rejects duplicate email | F10: Guest | G10: Register page is reachable. | H10: Email already registered | I10: 1. Open /register. 2. Fill fields according to test data. 3. Submit registration. 4. Observe validation or success flow. | J10: Validation rejects duplicate email and preserves entered non-sensitive fields. | L10: Not Run | M10: P1 | N10: High | O10: Validation | P10: Staging / QA | Q10: Chrome desktop + Android Chrome unless specified | R10: /register | S10: Maybe | T10: Yes | U10: Codex QA Generator
A11: TC-AUTH-010 | B11: TS-AUTH-002 | C11: Authentication | D11: Registration | E11: Register password confirmation mismatch | F11: Guest | G11: Register page is reachable. | H11: Password and confirmation differ | I11: 1. Open /register. 2. Fill fields according to test data. 3. Submit registration. 4. Observe validation or success flow. | J11: Validation rejects form and explains password confirmation mismatch. | L11: Not Run | M11: P1 | N11: High | O11: Validation | P11: Staging / QA | Q11: Chrome desktop + Android Chrome unless specified | R11: /register | S11: Maybe | T11: Yes | U11: Codex QA Generator
A12: TC-AUTH-011 | B12: TS-AUTH-003 | C12: Authentication | D12: Recovery / Verification / Passkey | E12: Forgot password accepts registered email | F12: Guest/User | G12: Relevant account exists where required. | H12: Registered email | I12: 1. Open or call /forgot-password. 2. Provide the test data. 3. Submit. 4. Observe response and account state. | J12: Reset/verification message is queued without exposing whether email exists beyond intended copy. | L12: Not Run | M12: P1 | N12: High | O12: Authentication | P12: Staging / QA | Q12: Chrome desktop + Android Chrome unless specified | R12: /forgot-password | S12: Maybe | T12: Yes | U12: Codex QA Generator
A13: TC-AUTH-012 | B13: TS-AUTH-003 | C13: Authentication | D13: Recovery / Verification / Passkey | E13: Reset password rejects invalid token | F13: Guest/User | G13: Relevant account exists where required. | H13: Invalid or expired token | I13: 1. Open or call /reset-password/{token}. 2. Provide the test data. 3. Submit. 4. Observe response and account state. | J13: Password is not changed and safe error is shown. | L13: Not Run | M13: P1 | N13: High | O13: Authentication | P13: Staging / QA | Q13: Chrome desktop + Android Chrome unless specified | R13: /reset-password/{token} | S13: Maybe | T13: Yes | U13: Codex QA Generator
... A196: TC-SEC-012 | B196: TS-SEC-001 | C196: Security | D196: Access Control / Input Validation | E196: Public cache bypasses authenticated responses | F196: All Roles | G196: Use QA accounts for guest, user, mitra, admin. Never run destructive payloads. | H196: Authorization header on public API request | I196: 1. Prepare role/session/payload. 2. Send request or submit form. 3. Verify status code, response content, logs, and data state. | J196: Private/authenticated data is not cached into public response. | L196: Not Run | M196: P1 | N196: High | O196: Security | P196: Staging / QA | Q196: Chrome desktop + Android Chrome unless specified | R196: middleware/routes/controllers/tests | S196: Yes | T196: Yes | U196: Codex QA Generator
A197: TC-RETIRE-001 | B197: TS-RETIRE-001 | C197: Retired/Partial Modules | D197: Legacy Surface | E197: Legacy route behavior for /admin/events | F197: Admin | G197: Use role indicated in test data. | H197: /admin/events | I197: 1. Open/call /admin/events. 2. Observe status and page content. 3. Confirm active wisata routes still work afterwards. | J197: 404/blocked because admin event surface is retired from active scope. | L197: Not Run | M197: P2 | N197: Medium | O197: Regression | P197: Staging / QA | Q197: Chrome desktop + Android Chrome unless specified | R197: /admin/events | S197: Maybe | T197: Yes | U197: Codex QA Generator | Y197: Marked partial/needs verification where business decision may change.
A198: TC-RETIRE-002 | B198: TS-RETIRE-001 | C198: Retired/Partial Modules | D198: Legacy Surface | E198: Legacy route behavior for /admin/academy/classes | F198: Admin | G198: Use role indicated in test data. | H198: /admin/academy/classes | I198: 1. Open/call /admin/academy/classes. 2. Observe status and page content. 3. Confirm active wisata routes still work afterwards. | J198: 404/blocked because academy surface is retired from active scope. | L198: Not Run | M198: P2 | N198: Medium | O198: Regression | P198: Staging / QA | Q198: Chrome desktop + Android Chrome unless specified | R198: /admin/academy/classes | S198: Maybe | T198: Yes | U198: Codex QA Generator | Y198: Marked partial/needs verification where business decision may change.
A199: TC-RETIRE-003 | B199: TS-RETIRE-001 | C199: Retired/Partial Modules | D199: Legacy Surface | E199: Legacy route behavior for /admin/retail-shop/products | F199: Admin | G199: Use role indicated in test data. | H199: /admin/retail-shop/products | I199: 1. Open/call /admin/retail-shop/products. 2. Observe status and page content. 3. Confirm active wisata routes still work afterwards. | J199: 404/blocked because retail surface is retired from active scope. | L199: Not Run | M199: P2 | N199: Medium | O199: Regression | P199: Staging / QA | Q199: Chrome desktop + Android Chrome unless specified | R199: /admin/retail-shop/products | S199: Maybe | T199: Yes | U199: Codex QA Generator | Y199: Marked partial/needs verification where business decision may change.
A200: TC-RETIRE-004 | B200: TS-RETIRE-001 | C200: Retired/Partial Modules | D200: Legacy Surface | E200: Legacy route behavior for /hotels | F200: Guest | G200: Use role indicated in test data. | H200: /hotels | I200: 1. Open/call /hotels. 2. Observe status and page content. 3. Confirm active wisata routes still work afterwards. | J200: 404/blocked from active public product surface. | L200: Not Run | M200: P2 | N200: Medium | O200: Regression | P200: Staging / QA | Q200: Chrome desktop + Android Chrome unless specified | R200: /hotels | S200: Maybe | T200: Yes | U200: Codex QA Generator | Y200: Marked partial/needs verification where business decision may change.
A201: TC-RETIRE-005 | B201: TS-RETIRE-001 | C201: Retired/Partial Modules | D201: Legacy Surface | E201: Legacy route behavior for /api/hotel/bookings/quote | F201: Mobile User | G201: Use role indicated in test data. | H201: /api/hotel/bookings/quote | I201: 1. Open/call /api/hotel/bookings/quote. 2. Observe status and page content. 3. Confirm active wisata routes still work afterwards. | J201: 404/blocked retired API surface. | L201: Not Run | M201: P2 | N201: Medium | O201: Regression | P201: Staging / QA | Q201: Chrome desktop + Android Chrome unless specified | R201: /api/hotel/bookings/quote | S201: Maybe | T201: Yes | U201: Codex QA Generator | Y201: Marked partial/needs verification where business decision may change.
A202: TC-RETIRE-006 | B202: TS-RETIRE-001 | C202: Retired/Partial Modules | D202: Legacy Surface | E202: Legacy route behavior for /affiliate | F202: Guest/User | G202: Use role indicated in test data. | H202: /affiliate | I202: 1. Open/call /affiliate. 2. Observe status and page content. 3. Confirm active wisata routes still work afterwards. | J202: Needs verification: affiliate pages exist but mobile affiliate APIs are retired; access should follow current business decision. | L202: Not Run | M202: P2 | N202: Medium | O202: Regression | P202: Staging / QA | Q202: Chrome desktop + Android Chrome unless specified | R202: /affiliate | S202: Maybe | T202: Yes | U202: Codex QA Generator | Y202: Marked partial/needs verification where business decision may change.
A203: TC-ADMIN-SYSTEM-001 | B203: TS-ADMIN-SYSTEM-001 | C203: Admin System | D203: Users / Notifications / Settings / Reset | E203: Create user from admin requires verified email defaults | F203: Admin | G203: Admin is authenticated. Use QA database only for destructive reset tests. | H203: Valid user data | I203: 1. Login as admin. 2. Open admin system/user page. 3. Submit specified payload/action. 4. Verify validation, status, and data safety. | J203: User is created with verified email where controller expects it. | L203: Not Run | M203: P1 | N203: High | O203: Functional | P203: Staging / QA | Q203: Chrome desktop + Android Chrome unless specified | R203: /admin/users, /admin/system/* | S203: Maybe | T203: Yes | U203: Codex QA Generator
A204: TC-ADMIN-SYSTEM-002 | B204: TS-ADMIN-SYSTEM-001 | C204: Admin System | D204: Users / Notifications / Settings / Reset | E204: Update user cannot modify admin accounts through user management | F204: Admin | G204: Admin is authenticated. Use QA database only for destructive reset tests. | H204: Admin target user | I204: 1. Login as admin. 2. Open admin system/user page. 3. Submit specified payload/action. 4. Verify validation, status, and data safety. | J204: Update is rejected/protected. | L204: Not Run | M204: P1 | N204: High | O204: Functional | P204: Staging / QA | Q204: Chrome desktop + Android Chrome unless specified | R204: /admin/users, /admin/system/* | S204: Maybe | T204: Yes | U204: Codex QA Generator
A205: TC-ADMIN-SYSTEM-003 | B205: TS-ADMIN-SYSTEM-001 | C205: Admin System | D205: Users / Notifications / Settings / Reset | E205: Delete user removes related operational data but protects admins | F205: Admin | G205: Admin is authenticated. Use QA database only for destructive reset tests. | H205: Normal user and admin user | I205: 1. Login as admin. 2. Open admin system/user page. 3. Submit specified payload/action. 4. Verify validation, status, and data safety. | J205: Normal user deletion cleans related data; admin deletion blocked. | L205: Not Run | M205: P1 | N205: High | O205: Functional | P205: Staging / QA | Q205: Chrome desktop + Android Chrome unless specified | R205: /admin/users, /admin/system/* | S205: Maybe | T205: Yes | U205: Codex QA Generator
A206: TC-ADMIN-SYSTEM-004 | B206: TS-ADMIN-SYSTEM-001 | C206: Admin System | D206: Users / Notifications / Settings / Reset | E206: Broadcast notification validates title/message/target | F206: Admin | G206: Admin is authenticated. Use QA database only for destructive reset tests. | H206: Valid and invalid broadcast payload | I206: 1. Login as admin. 2. Open admin system/user page. 3. Submit specified payload/action. 4. Verify validation, status, and data safety. | J206: Valid notification created; invalid payload rejected. | L206: Not Run | M206: P1 | N206: High | O206: Functional | P206: Staging / QA | Q206: Chrome desktop + Android Chrome unless specified | R206: /admin/users, /admin/system/* | S206: Maybe | T206: Yes | U206: Codex QA Generator
A207: TC-ADMIN-SYSTEM-005 | B207: TS-ADMIN-SYSTEM-001 | C207: Admin System | D207: Users / Notifications / Settings / Reset | E207: System settings update booking timeout for wisata | F207: Admin | G207: Admin is authenticated. Use QA database only for destructive reset tests. | H207: Valid timeout numbers | I207: 1. Login as admin. 2. Open admin system/user page. 3. Submit specified payload/action. 4. Verify validation, status, and data safety. | J207: Wisata timeout persists; retired product keys behavior follows current code. | L207: Not Run | M207: P1 | N207: High | O207: Functional | P207: Staging / QA | Q207: Chrome desktop + Android Chrome unless specified | R207: /admin/users, /admin/system/* | S207: Maybe | T207: Yes | U207: Codex QA Generator
A208: TC-ADMIN-SYSTEM-006 | B208: TS-ADMIN-SYSTEM-001 | C208: Admin System | D208: Users / Notifications / Settings / Reset | E208: System reset requires exact confirmation text | F208: Admin | G208: Admin is authenticated. Use QA database only for destructive reset tests. | H208: Wrong confirmation | I208: 1. Login as admin. 2. Open admin system/user page. 3. Submit specified payload/action. 4. Verify validation, status, and data safety. | J208: Reset rejected and no data deleted. | L208: Not Run | M208: P0 | N208: Critical | O208: Functional | P208: Staging / QA | Q208: Chrome desktop + Android Chrome unless specified | R208: /admin/users, /admin/system/* | S208: Maybe | T208: Yes | U208: Codex QA Generator
A209: TC-ADMIN-SYSTEM-007 | B209: TS-ADMIN-SYSTEM-001 | C209: Admin System | D209: Users / Notifications / Settings / Reset | E209: System reset selected sections preserve admin accounts | F209: Admin | G209: Admin is authenticated. Use QA database only for destructive reset tests. | H209: Selected operational sections | I209: 1. Login as admin. 2. Open admin system/user page. 3. Submit specified payload/action. 4. Verify validation, status, and data safety. | J209: Operational data reset safely, admin accounts preserved. | L209: Not Run | M209: P0 | N209: Critical | O209: Functional | P209: Staging / QA | Q209: Chrome desktop + Android Chrome unless specified | R209: /admin/users, /admin/system/* | S209: Maybe | T209: Yes | U209: Codex QA Generator
A210: TC-ADMIN-SYSTEM-008 | B210: TS-ADMIN-SYSTEM-001 | C210: Admin System | D210: Users / Notifications / Settings / Reset | E210: Audit logs filters by actor/action/date | F210: Admin | G210: Admin is authenticated. Use QA database only for destructive reset tests. | H210: Filter criteria | I210: 1. Login as admin. 2. Open admin system/user page. 3. Submit specified payload/action. 4. Verify validation, status, and data safety. | J210: Audit log list narrows to matching records. | L210: Not Run | M210: P1 | N210: High | O210: Functional | P210: Staging / QA | Q210: Chrome desktop + Android Chrome unless specified | R210: /admin/users, /admin/system/* | S210: Maybe | T210: Yes | U210: Codex QA Generator

Sheet Regression Suite
A1: Regression ID | B1: Test Case ID | C1: Module | D1: Test Case | E1: Priority | F1: Reason Included | G1: Status | H1: Last Executed
A2: RG-001 | B2: TC-AUTH-001 | C2: Authentication | D2: Login with valid user credentials | E2: P0 | F2: P0/P1 critical path or access/data-integrity risk | G2: Not Run
A3: RG-002 | B3: TC-AUTH-002 | C3: Authentication | D3: Login rejects invalid password | E3: P0 | F3: P0/P1 critical path or access/data-integrity risk | G3: Not Run
A4: RG-003 | B4: TC-AUTH-003 | C4: Authentication | D4: Login rejects empty credentials | E4: P1 | F4: P0/P1 critical path or access/data-integrity risk | G4: Not Run
A5: RG-004 | B5: TC-AUTH-004 | C5: Authentication | D5: Login rate limit is enforced | E5: P1 | F5: P0/P1 critical path or access/data-integrity risk | G5: Not Run
A6: RG-005 | B6: TC-AUTH-006 | C6: Authentication | D6: Register with valid required fields | E6: P0 | F6: P0/P1 critical path or access/data-integrity risk | G6: Not Run
A7: RG-006 | B7: TC-AUTH-007 | C7: Authentication | D7: Register rejects missing phone/WhatsApp | E7: P0 | F7: P0/P1 critical path or access/data-integrity risk | G7: Not Run
A8: RG-007 | B8: TC-AUTH-008 | C8: Authentication | D8: Register rejects unchecked legal terms | E8: P0 | F8: P0/P1 critical path or access/data-integrity risk | G8: Not Run
A9: RG-008 | B9: TC-AUTH-009 | C9: Authentication | D9: Register rejects duplicate email | E9: P1 | F9: P0/P1 critical path or access/data-integrity risk | G9: Not Run
A10: RG-009 | B10: TC-AUTH-010 | C10: Authentication | D10: Register password confirmation mismatch | E10: P1 | F10: P0/P1 critical path or access/data-integrity risk | G10: Not Run
A11: RG-010 | B11: TC-AUTH-011 | C11: Authentication | D11: Forgot password accepts registered email | E11: P1 | F11: P0/P1 critical path or access/data-integrity risk | G11: Not Run
A12: RG-011 | B12: TC-AUTH-012 | C12: Authentication | D12: Reset password rejects invalid token | E12: P1 | F12: P0/P1 critical path or access/data-integrity risk | G12: Not Run
A13: RG-012 | B13: TC-AUTH-013 | C13: Authentication | D13: Email verification link validates signature | E13: P1 | F13: P0/P1 critical path or access/data-integrity risk | G13: Not Run
... A91: RG-090 | B91: TC-ADMIN-CONTENT-108 | C91: Admin Public Content | D91: About rejects invalid or oversized input | E91: P1 | F91: P0/P1 critical path or access/data-integrity risk | G91: Not Run

Sheet Smoke Test
A1: Smoke ID | B1: Module | C1: Test | D1: Expected Result | E1: Priority | F1: Status | G1: Notes
A2: SMK-001 | B2: Public Home | C2: Open homepage / | D2: Homepage returns 200 and renders banner/category/promo sections. | E2: P0 | F2: Not Run
A3: SMK-002 | B3: Public Catalog | C3: Open /wisata | D3: Wisata listing returns 200 with no horizontal overflow in desktop/mobile smoke. | E3: P0 | F3: Not Run
A4: SMK-003 | B4: Wisata Detail | C4: Open a live destination detail | D4: Detail page loads with ticket availability state. | E4: P0 | F4: Not Run
A5: SMK-004 | B5: Authentication | C5: Login valid user | D5: User can authenticate and reach user flow. | E5: P0 | F5: Not Run
A6: SMK-005 | B6: Booking | C6: Prepare wisata booking | D6: User can reach booking review for valid ticket. | E6: P0 | F6: Not Run
A7: SMK-006 | B7: Admin | C7: Open admin dashboard | D7: Admin dashboard returns 200 and shows wisata-focused metrics. | E7: P0 | F7: Not Run
A8: SMK-007 | B8: Admin Wisata | C8: Open admin wisata destinations | D8: Destination table/page is usable. | E8: P0 | F8: Not Run
A9: SMK-008 | B9: Admin Voucher | C9: Open /admin/wisata/vouchers | D9: Voucher modal/list is usable. | E9: P1 | F9: Not Run
A10: SMK-009 | B10: Mitra Dashboard | C10: Open mitra dashboard | D10: Mitra dashboard loads for verified wisata partner. | E10: P0 | F10: Not Run
A11: SMK-010 | B11: Mitra QR | C11: Open /mitra/wisata/scans?tab=qr | D11: QR tab renders poster preview and download action. | E11: P1 | F11: Not Run
A12: SMK-011 | B12: Mobile API | C12: GET /api/discovery/metadata | D12: API returns wisata-only metadata. | E12: P1 | F12: Not Run
A13: SMK-012 | B13: Security | C13: Open retired /events route | D13: Retired route is blocked. | E13: P1 | F13: Not Run

Sheet Access Control
A1: Feature / Route | B1: Guest | C1: User | D1: Admin | E1: Mitra | F1: Custom Admin / Staff | G1: Expected Enforcement
A2: Home / | B2: Allowed | C2: Allowed | D2: Allowed | E2: Allowed | F2: Allowed | G2: Public route; no auth required
A3: Promo /promo | B3: Allowed | C3: Allowed | D3: Allowed | E3: Allowed | F3: Allowed | G3: Public promo discovery
A4: Wisata catalog /wisata | B4: Allowed | C4: Allowed | D4: Allowed | E4: Allowed | F4: Allowed | G4: Public listing
A5: Wisata checkout /wisata/booking/review | B5: Denied | C5: Allowed | D5: Denied | E5: Denied | F5: Denied | G5: Requires user role with booking draft
A6: User history /history | B6: Denied | C6: Allowed | D6: Denied | E6: Denied | F6: Denied | G6: Auth user-owned data
A7: Ticket scan /tickets/scan | B7: Denied | C7: Allowed | D7: Denied | E7: Denied | F7: Denied | G7: User scans mitra QR
A8: Admin dashboard /dashboard | B8: Denied | C8: Denied | D8: Allowed | E8: Denied | F8: Conditional | G8: admin middleware
A9: Admin public content /admin/public/* | B9: Denied | C9: Denied | D9: Allowed | E9: Denied | F9: Conditional | G9: admin + permission registry
A10: Admin wisata destinations | B10: Denied | C10: Denied | D10: Allowed | E10: Denied | F10: Conditional | G10: admin wisata permission
A11: Admin wisata vouchers | B11: Denied | C11: Denied | D11: Allowed | E11: Denied | F11: Conditional | G11: admin wisata voucher permission
A12: Admin mitra wisata | B12: Denied | C12: Denied | D12: Allowed | E12: Denied | F12: Conditional | G12: admin mitra wisata permission
... A21: Retired hotel/event/academy routes | B21: Denied | C21: Denied | D21: Denied | E21: Denied | F21: Denied | G21: BlockRetiredProductFeatures 404

Sheet Security Test
A1: Security Test ID | B1: Area | C1: Scenario | D1: Attack / Misuse Case | E1: Expected Protection | F1: Severity | G1: Status | H1: Notes
A2: ST-SEC-001 | B2: Access Control / Input Validation | C2: Guest cannot access admin dashboard | D2: GET /dashboard as guest | E2: Redirect to login or deny; no admin data returned. | F2: High | G2: Not Run
A3: ST-SEC-002 | B3: Access Control / Input Validation | C3: User cannot access admin wisata routes | D3: GET /admin/wisata/destinations as user | E3: 403/redirect/404 according to middleware; no data returned. | F3: Critical | G3: Not Run
A4: ST-SEC-003 | B4: Access Control / Input Validation | C4: Mitra cannot access admin-only routes | D4: GET /admin/users as mitra | E4: Access denied. | F4: Critical | G4: Not Run
A5: ST-SEC-004 | B5: Access Control / Input Validation | C5: Mitra cannot open retired hotel/event operational routes | D5: GET /mitra/events or /mitra/hotels | E5: 404 via retired feature block. | F5: High | G5: Not Run
A6: ST-SEC-005 | B6: Access Control / Input Validation | C6: Retired public product routes are blocked | D6: GET /events, /hotels, /academy, /retail-shop | E6: 404 or retired behavior, not active product listing. | F6: High | G6: Not Run
A7: ST-SEC-006 | B7: Access Control / Input Validation | C7: CSRF blocks state-changing web request without token | D7: POST admin/public/home without CSRF | E7: Request rejected with CSRF/session protection. | F7: High | G7: Not Run
A8: ST-SEC-007 | B8: Access Control / Input Validation | C8: XSS payload is escaped/sanitized in rich content | D8: <script>alert(1)</script> in editable content | E8: Script is removed/escaped and not executable on public page. | F8: High | G8: Not Run
A9: ST-SEC-008 | B9: Access Control / Input Validation | C9: SQL injection string in search is handled safely | D9: q=%' OR 1=1 -- | E9: No SQL error; results remain scoped. | F9: High | G9: Not Run
A10: ST-SEC-009 | B10: Access Control / Input Validation | C10: File upload rejects executable disguised as image | D10: malware.php.jpg or invalid MIME | E10: Upload validation rejects or stores safely outside executable path. | F10: High | G10: Not Run
A11: ST-SEC-010 | B11: Access Control / Input Validation | C11: Mass assignment cannot set owner/status fields | D11: mitra_id/owner_id/is_admin in request payload | E11: Sensitive fields ignored or rejected. | F11: Critical | G11: Not Run
A12: ST-SEC-011 | B12: Access Control / Input Validation | C12: Admin audit log redacts password/token fields | D12: Payload with password/token | E12: Log UI/API does not expose sensitive values. | F12: High | G12: Not Run
A13: ST-SEC-012 | B13: Access Control / Input Validation | C13: Public cache bypasses authenticated responses | D13: Authorization header on public API request | E13: Private/authenticated data is not cached into public response. | F13: High | G13: Not Run
... A17: ST-XSS-002 | B17: Stored XSS | C17: Public content rich text XSS | D17: Submit script/event handler in admin editable content | E17: Sanitizer removes executable HTML while safe formatting remains | F17: High | G17: Not Run

Sheet Compatibility Test
A1: Platform | B1: Browser | C1: Viewport | D1: Test Area | E1: Expected | F1: Status | G1: Notes
A2: Desktop | B2: Chrome | C2: 1366x768 | D2: Homepage / Catalog / Detail / Checkout / Admin table / Mitra QR | E2: No horizontal overflow, readable text, touch/click targets usable, no console blocking error | F2: Not Run | G2: Representative routes may be selected per role.
A3: Desktop | B3: Chrome | C3: 1440x900 | D3: Homepage / Catalog / Detail / Checkout / Admin table / Mitra QR | E3: No horizontal overflow, readable text, touch/click targets usable, no console blocking error | F3: Not Run | G3: Representative routes may be selected per role.
A4: Desktop | B4: Firefox | C4: 1366x768 | D4: Homepage / Catalog / Detail / Checkout / Admin table / Mitra QR | E4: No horizontal overflow, readable text, touch/click targets usable, no console blocking error | F4: Not Run | G4: Representative routes may be selected per role.
A5: Desktop | B5: Firefox | C5: 1440x900 | D5: Homepage / Catalog / Detail / Checkout / Admin table / Mitra QR | E5: No horizontal overflow, readable text, touch/click targets usable, no console blocking error | F5: Not Run | G5: Representative routes may be selected per role.
A6: Desktop | B6: Edge | C6: 1366x768 | D6: Homepage / Catalog / Detail / Checkout / Admin table / Mitra QR | E6: No horizontal overflow, readable text, touch/click targets usable, no console blocking error | F6: Not Run | G6: Representative routes may be selected per role.
A7: Desktop | B7: Edge | C7: 1440x900 | D7: Homepage / Catalog / Detail / Checkout / Admin table / Mitra QR | E7: No horizontal overflow, readable text, touch/click targets usable, no console blocking error | F7: Not Run | G7: Representative routes may be selected per role.
A8: Android | B8: Chrome | C8: 360x800 | D8: Homepage / Catalog / Detail / Checkout / Admin table / Mitra QR | E8: No horizontal overflow, readable text, touch/click targets usable, no console blocking error | F8: Not Run | G8: Representative routes may be selected per role.
A9: Android | B9: Chrome | C9: 375x812 | D9: Homepage / Catalog / Detail / Checkout / Admin table / Mitra QR | E9: No horizontal overflow, readable text, touch/click targets usable, no console blocking error | F9: Not Run | G9: Representative routes may be selected per role.
A10: Android | B10: Chrome | C10: 390x844 | D10: Homepage / Catalog / Detail / Checkout / Admin table / Mitra QR | E10: No horizontal overflow, readable text, touch/click targets usable, no console blocking error | F10: Not Run | G10: Representative routes may be selected per role.
A11: Android | B11: Chrome | C11: 430x932 | D11: Homepage / Catalog / Detail / Checkout / Admin table / Mitra QR | E11: No horizontal overflow, readable text, touch/click targets usable, no console blocking error | F11: Not Run | G11: Representative routes may be selected per role.
A12: Android | B12: Chrome | C12: 768x1024 | D12: Homepage / Catalog / Detail / Checkout / Admin table / Mitra QR | E12: No horizontal overflow, readable text, touch/click targets usable, no console blocking error | F12: Not Run | G12: Representative routes may be selected per role.
... A24: Tablet | B24: Safari/Chrome | C24: 1440x900 | D24: Homepage / Catalog / Detail / Checkout / Admin table / Mitra QR | E24: No horizontal overflow, readable text, touch/click targets usable, no console blocking error | F24: Not Run | G24: Representative routes may be selected per role.

Sheet Traceability Matrix
A1: Requirement ID | B1: Module | C1: Requirement / Feature | D1: Route / Source | E1: Scenario ID | F1: Test Case IDs | G1: Coverage Status | H1: Notes
A2: REQ-AUTH-001 | B2: Authentication | C2: Users can register, login, logout, verify email, reset password, use 2FA/passkeys where configured | D2: /login, /register, /forgot-password, /api/auth/* | E2: TS-AUTH-001, TS-AUTH-002, TS-AUTH-003 | F2: TC-AUTH-001, TC-AUTH-002, TC-AUTH-003, TC-AUTH-004, TC-AUTH-005, TC-AUTH-006, TC-AUTH-007, TC-AUTH-008, TC-AUTH-009, TC-AUTH-010, TC-AUTH-011, TC-AUTH-012, TC-AUTH-013, TC-AUTH-014, TC-AUTH-015 | G2: Covered
A3: REQ-USER-001 | B3: User Account | C3: Authenticated users can manage profile, password, social/media settings, notifications, and history | D3: /settings/profile, /settings/password, /notifications, /history, /api/profile/* | E3: TS-USER-001 | F3: TC-USER-001, TC-USER-002, TC-USER-003, TC-USER-004, TC-USER-005, TC-USER-006, TC-USER-007, TC-USER-008, TC-USER-009, TC-USER-010 | G3: Covered
A4: REQ-HOME-001 | B4: Public Home | C4: Homepage displays tourism-first banner, categories, promo special, partner, part-of, and product sections from managed content | D4: /, /admin/public/home, /api/mobile/home | E4: TS-HOME-001 | F4: TC-HOME-001, TC-HOME-002, TC-HOME-003, TC-HOME-004, TC-HOME-005, TC-HOME-006, TC-HOME-007, TC-HOME-008, TC-HOME-009, TC-HOME-010 | G4: Covered
A5: REQ-CONTENT-001 | B5: Public Content | C5: Admin can manage public banners, partners, part-of logos, FAQ, contact, about, privacy, promo items/videos | D5: /admin/public/* | E5: TS-ADMIN-CONTENT-001 | F5: TC-ADMIN-CONTENT-001, TC-ADMIN-CONTENT-101, TC-ADMIN-CONTENT-002, TC-ADMIN-CONTENT-102, TC-ADMIN-CONTENT-003, TC-ADMIN-CONTENT-103, TC-ADMIN-CONTENT-004, TC-ADMIN-CONTENT-104, TC-ADMIN-CONTENT-005, TC-ADMIN-CONTENT-105, TC-ADMIN-CONTENT-006, TC-ADMIN-CONTENT-106, TC-ADMIN-CONTENT-007, TC-ADMIN-CONTENT-107, TC-ADMIN-CONTENT-008, TC-ADMIN-CONTENT-108, TC-ADMIN-CONTENT-009, TC-ADMIN-CONTENT-109, TC-ADMIN-CONTENT-010, TC-ADMIN-CONTENT-110 | G5: Covered
A6: REQ-WISATA-CATALOG-001 | B6: Wisata Catalog | C6: Public users can search and filter live wisata destinations and open details | D6: /wisata, /wisata/{destination}, /api/products/wisata | E6: TS-CATALOG-001, TS-WISATA-DETAIL-001 | F6: TC-CATALOG-001, TC-CATALOG-002, TC-CATALOG-003, TC-CATALOG-004, TC-CATALOG-005, TC-CATALOG-006, TC-CATALOG-007, TC-CATALOG-008, TC-CATALOG-009, TC-CATALOG-010, TC-WISATA-DETAIL-001, TC-WISATA-DETAIL-002, TC-WISATA-DETAIL-003, TC-WISATA-DETAIL-004, TC-WISATA-DETAIL-005, TC-WISATA-DETAIL-006, TC-WISATA-DETAIL-007, TC-WISATA-DETAIL-008, TC-WISATA-DETAIL-009, TC-WISATA-DETAIL-010 | G6: Covered
A7: REQ-WISATA-BOOKING-001 | B7: Wisata Booking | C7: Users can select tickets, apply voucher, create booking, pay, view e-ticket, and receive scan-ready ticket | D7: /wisata/booking/*, /api/wisata/bookings/* | E7: TS-WISATA-BOOKING-001 | F7: TC-WISATA-BOOKING-001, TC-WISATA-BOOKING-002, TC-WISATA-BOOKING-003, TC-WISATA-BOOKING-004, TC-WISATA-BOOKING-005, TC-WISATA-BOOKING-006, TC-WISATA-BOOKING-007, TC-WISATA-BOOKING-008, TC-WISATA-BOOKING-009, TC-WISATA-BOOKING-010, TC-WISATA-BOOKING-011, TC-WISATA-BOOKING-012, TC-WISATA-BOOKING-013, TC-WISATA-BOOKING-014, TC-WISATA-BOOKING-015, TC-WISATA-BOOKING-016, TC-WISATA-BOOKING-017, TC-WISATA-BOOKING-018 | G7: Covered
A8: REQ-WISATA-SCAN-001 | B8: Wisata Ticket Scan | C8: Users scan mitra QR, select owned paid ticket item, and ticket can only be used once | D8: /tickets/scan, /api/wisata/ticket-scans/* | E8: TS-WISATA-SCAN-001 | F8: TC-WISATA-SCAN-001, TC-WISATA-SCAN-002, TC-WISATA-SCAN-003, TC-WISATA-SCAN-004, TC-WISATA-SCAN-005, TC-WISATA-SCAN-006, TC-WISATA-SCAN-007, TC-WISATA-SCAN-008, TC-WISATA-SCAN-009, TC-WISATA-SCAN-010 | G8: Covered
A9: REQ-ADMIN-WISATA-001 | B9: Admin Wisata | C9: Admin can manage wisata destinations, tickets/packages, bookings, scans, content moderation, exceptions, finance, and vouchers | D9: /admin/wisata/* | E9: TS-ADMIN-WISATA-001 | F9: TC-ADMIN-WISATA-001, TC-ADMIN-WISATA-002, TC-ADMIN-WISATA-003, TC-ADMIN-WISATA-004, TC-ADMIN-WISATA-005, TC-ADMIN-WISATA-006, TC-ADMIN-WISATA-007, TC-ADMIN-WISATA-008, TC-ADMIN-WISATA-009, TC-ADMIN-WISATA-010, TC-ADMIN-WISATA-011, TC-ADMIN-WISATA-012, TC-ADMIN-WISATA-013, TC-ADMIN-WISATA-014, TC-ADMIN-WISATA-015, TC-ADMIN-WISATA-016, TC-ADMIN-WISATA-017, TC-ADMIN-WISATA-018, TC-ADMIN-WISATA-019, TC-ADMIN-WISATA-020, TC-ADMIN-WISATA-021, TC-ADMIN-WISATA-022, TC-ADMIN-WISATA-023, TC-ADMIN-WISATA-024, TC-ADMIN-WISATA-025 | G9: Covered
A10: REQ-ADMIN-MITRA-001 | B10: Admin Mitra Wisata | C10: Admin can manage wisata partners, onboarding status, verification, suspension, documents, payout status | D10: /admin/mitra-wisata, /admin/mitra-documents | E10: TS-ADMIN-MITRA-001 | F10: TC-ADMIN-MITRA-001, TC-ADMIN-MITRA-002, TC-ADMIN-MITRA-003, TC-ADMIN-MITRA-004, TC-ADMIN-MITRA-005, TC-ADMIN-MITRA-006, TC-ADMIN-MITRA-007 | G10: Covered
A11: REQ-MITRA-001 | B11: Mitra Wisata | C11: Mitra can manage owned wisata profile, tickets, bookings, QR poster, scans, staff, finance, disputes, reviews | D11: /mitra/wisata/* | E11: TS-MITRA-001 | F11: TC-MITRA-001, TC-MITRA-002, TC-MITRA-003, TC-MITRA-004, TC-MITRA-005, TC-MITRA-006, TC-MITRA-007, TC-MITRA-008, TC-MITRA-009, TC-MITRA-010, TC-MITRA-011, TC-MITRA-012, TC-MITRA-013, TC-MITRA-014, TC-MITRA-015, TC-MITRA-016, TC-MITRA-017, TC-MITRA-018, TC-MITRA-019, TC-MITRA-020 | G11: Covered
A12: REQ-API-001 | B12: Mobile API | C12: Mobile app can use auth, discovery, public content, wisata booking, ticket scan, notifications, profile, chat, reviews | D12: /api/* | E12: TS-API-001 | F12: TC-API-001, TC-API-002, TC-API-003, TC-API-004, TC-API-005, TC-API-006, TC-API-007, TC-API-008, TC-API-009, TC-API-010, TC-API-011, TC-API-012, TC-API-013, TC-API-014, TC-API-015, TC-API-016, TC-API-017, TC-API-018, TC-API-019, TC-API-020, TC-API-021, TC-API-022, TC-API-023, TC-API-024, TC-API-025, TC-API-026, TC-API-027, TC-API-028 | G12: Covered
A13: REQ-SEC-001 | B13: Security & Access Control | C13: Routes enforce auth, role, verified state, CSRF/session/Sanctum protection, object ownership, and retired module blocking | D13: middleware, routes, tests | E13: TS-SEC-001 | F13: TC-SEC-001, TC-SEC-002, TC-SEC-003, TC-SEC-004, TC-SEC-005, TC-SEC-006, TC-SEC-007, TC-SEC-008, TC-SEC-009, TC-SEC-010, TC-SEC-011, TC-SEC-012 | G13: Covered
A14: REQ-RETIRE-001 | B14: Retired Product Features | C14: Legacy hotel/event/academy/retail surfaces are blocked from active product surface unless explicitly retained/admin-only | D14: BlockRetiredProductFeatures | E14: TS-RETIRE-001 | F14: TC-RETIRE-001, TC-RETIRE-002, TC-RETIRE-003, TC-RETIRE-004, TC-RETIRE-005, TC-RETIRE-006 | G14: Covered

Sheet Bug Report
A1: Bug ID | B1: Title | C1: Module | D1: Related Test Case | E1: Environment | F1: Precondition | G1: Steps to Reproduce | H1: Actual Result | I1: Expected Result | J1: Severity | K1: Priority | L1: Status | M1: Assignee | N1: Reporter | O1: Reported Date | P1: Resolved Date | Q1: Retest Status | R1: Screenshot / Evidence | S1: Notes
A2: BUG-001 | E2: QA/Staging | L2: New | Q2: Not Run
A3: BUG-002 | E3: QA/Staging | L3: New | Q3: Not Run
A4: BUG-003 | E4: QA/Staging | L4: New | Q4: Not Run
A5: BUG-004 | E5: QA/Staging | L5: New | Q5: Not Run
A6: BUG-005 | E6: QA/Staging | L6: New | Q6: Not Run
A7: BUG-006 | E7: QA/Staging | L7: New | Q7: Not Run
A8: BUG-007 | E8: QA/Staging | L8: New | Q8: Not Run
A9: BUG-008 | E9: QA/Staging | L9: New | Q9: Not Run
A10: BUG-009 | E10: QA/Staging | L10: New | Q10: Not Run
A11: BUG-010 | E11: QA/Staging | L11: New | Q11: Not Run
A12: BUG-011 | E12: QA/Staging | L12: New | Q12: Not Run
A13: BUG-012 | E13: QA/Staging | L13: New | Q13: Not Run
... A16: BUG-015 | E16: QA/Staging | L16: New | Q16: Not Run

Sheet Test Execution
A1: Execution ID | B1: Test Cycle | C1: Test Case ID | D1: Tester | E1: Execution Date | F1: Environment | G1: Build / Version | H1: Status | I1: Bug ID | J1: Comment
A2: EXE-001 | B2: Cycle 1 | C2: TC-AUTH-001 | F2: QA/Staging | H2: Not Run
A3: EXE-002 | B3: Cycle 1 | C3: TC-AUTH-002 | F3: QA/Staging | H3: Not Run
A4: EXE-003 | B4: Cycle 1 | C4: TC-AUTH-003 | F4: QA/Staging | H4: Not Run
A5: EXE-004 | B5: Cycle 1 | C5: TC-AUTH-004 | F5: QA/Staging | H5: Not Run
A6: EXE-005 | B6: Cycle 1 | C6: TC-AUTH-005 | F6: QA/Staging | H6: Not Run
A7: EXE-006 | B7: Cycle 1 | C7: TC-AUTH-006 | F7: QA/Staging | H7: Not Run
A8: EXE-007 | B8: Cycle 1 | C8: TC-AUTH-007 | F8: QA/Staging | H8: Not Run
A9: EXE-008 | B9: Cycle 1 | C9: TC-AUTH-008 | F9: QA/Staging | H9: Not Run
A10: EXE-009 | B10: Cycle 1 | C10: TC-AUTH-009 | F10: QA/Staging | H10: Not Run
A11: EXE-010 | B11: Cycle 1 | C11: TC-AUTH-010 | F11: QA/Staging | H11: Not Run
A12: EXE-011 | B12: Cycle 1 | C12: TC-AUTH-011 | F12: QA/Staging | H12: Not Run
A13: EXE-012 | B13: Cycle 1 | C13: TC-AUTH-012 | F13: QA/Staging | H13: Not Run
... A210: EXE-209 | B210: Cycle 1 | C210: TC-ADMIN-SYSTEM-008 | F210: QA/Staging | H210: Not Run

Sheet Test Environment
A1: Environment Item | B1: Value | C1: Purpose | D1: Status | E1: Notes
A2: Backend Runtime | B2: PHP ^8.2; Laravel ^12.0 | C2: Serve web/API routes | D2: Needs QA Setup | E2: Version from composer.json
A3: Frontend | B3: React ^19.2.0; Inertia ^2.3.7; TypeScript; Tailwind ^4.0.0 | C3: Browser UI | D3: Needs QA Setup | E3: Version from package.json
A4: Database | B4: Laravel database connection from environment | C4: Persistent app data | D4: Needs QA Setup | E4: Do not record secrets in this workbook
A5: Storage | B5: Laravel public storage / uploaded media | C5: Banners, partner logos, QR logos, wisata photos, ticket PDFs | D5: Needs QA Setup | E5: storage:link expected in deployment
A6: Mail | B6: Sandbox/fake SMTP recommended | C6: Email verification, password reset, ticket email | D6: Needs QA Setup | E6: Do not use production recipients
A7: Payment | B7: Midtrans sandbox/fake mode | C7: Booking payment snap/redirect/callback | D7: Needs QA Setup | E7: No real charge during QA
A8: Cache/Queue | B8: Redis optional; Laravel cache; Reverb/Pusher stack present | C8: Public API cache, notifications/realtime where configured | D8: Needs Verification | E8: Redis tests may skip if runtime unavailable
A9: Mobile API Client | B9: Postman/Insomnia/curl or Flutter QA build | C9: Sanctum API and mobile flows | D9: Needs QA Setup | E9: Use dummy accounts only
A10: Browsers | B10: Chrome, Firefox, Edge, Android Chrome, iOS Safari | C10: Compatibility testing | D10: Not Run | E10: See Compatibility Test sheet
A11: Automated Tests | B11: Pest/PHPUnit feature/unit tests exist | C11: Reference regression automation | D11: Needs Verification | E11: Manual statuses remain Not Run

Sheet QA Checklist
A1: Checklist ID | B1: Category | C1: Check | D1: Required | E1: Status | F1: Evidence | G1: Notes
A2: CHK-001 | B2: Functional | C2: All P0 test cases executed and passed | D2: Yes | E2: Not Run
A3: CHK-002 | B3: Security | C3: No open Critical security/access-control defect | D3: Yes | E3: Not Run
A4: CHK-003 | B4: Security | C4: Guest/user/mitra/admin access matrix verified | D4: Yes | E4: Not Run
A5: CHK-004 | B5: Authentication | C5: Login/register/password reset/email verification smoke passed | D5: Yes | E5: Not Run
A6: CHK-005 | B6: Booking | C6: Wisata booking + payment sandbox + e-ticket flow passed | D6: Yes | E6: Not Run
A7: CHK-006 | B7: QR Scan | C7: Mitra QR + user scan + one-time ticket usage passed | D7: Yes | E7: Not Run
A8: CHK-007 | B8: Admin | C8: Admin wisata, voucher, content, and mitra management smoke passed | D8: Yes | E8: Not Run
A9: CHK-008 | B9: Mitra | C9: Mitra dashboard/destination/ticket/booking/QR smoke passed | D9: Yes | E9: Not Run
A10: CHK-009 | B10: Responsive | C10: Mobile and desktop representative routes checked | D10: Yes | E10: Not Run
A11: CHK-010 | B11: Compatibility | C11: Chrome/Firefox/Edge/Android/iOS representative pass | D11: No | E11: Not Run
A12: CHK-011 | B12: Data | C12: No orphan/cross-owner data found in QA checks | D12: Yes | E12: Not Run
A13: CHK-012 | B13: Deployment | C13: Storage link, env, queue/cache/payment/mail sandbox verified | D13: Yes | E13: Not Run
... A16: CHK-015 | B16: Documentation | C16: Known issues and release notes updated | D16: Yes | E16: Not Run

Sheet Dashboard
A1: Metric | B1: Formula / Value | C1: Notes
A2: Total Test Cases | B2: =COUNTA('Test Cases'!$A$2:$A$1000) | C2: All manual test cases in workbook
A3: Executed | B3: =COUNTIFS('Test Cases'!$L$2:$L$1000,"<>Not Run",'Test Cases'!$L$2:$L$1000,"<>") | C3: Passed + Failed + Blocked + Retest + Skipped + N/A
A4: Not Run | B4: =COUNTIF('Test Cases'!$L$2:$L$1000,"Not Run") | C4: Default initial status
A5: Passed | B5: =COUNTIF('Test Cases'!$L$2:$L$1000,"Passed")
A6: Failed | B6: =COUNTIF('Test Cases'!$L$2:$L$1000,"Failed")
A7: Blocked | B7: =COUNTIF('Test Cases'!$L$2:$L$1000,"Blocked")
A8: Retest | B8: =COUNTIF('Test Cases'!$L$2:$L$1000,"Retest")
A9: Pass Rate | B9: =IFERROR(B5/B2,0) | C9: Formula updates when QA changes status
A10: Failure Rate | B10: =IFERROR(B6/B2,0) | C10: Formula updates when QA changes status
A11: Execution Progress | B11: =IFERROR(B3/B2,0) | C11: Formula updates when QA changes status
A12: P0 | B12: =COUNTIF('Test Cases'!$M$2:$M$1000,"P0") | C12: Critical business risk
A13: P1 | B13: =COUNTIF('Test Cases'!$M$2:$M$1000,"P1") | C13: High priority
A14: P2 | B14: =COUNTIF('Test Cases'!$M$2:$M$1000,"P2") | C14: Medium priority
A15: P3 | B15: =COUNTIF('Test Cases'!$M$2:$M$1000,"P3") | C15: Low priority
A17: Tests by Module | B17: Count
A18: Mobile API | B18: =COUNTIF('Test Cases'!$C$2:$C$1000,"Mobile API")
A19: Admin Wisata | B19: =COUNTIF('Test Cases'!$C$2:$C$1000,"Admin Wisata")
A20: Admin Public Content | B20: =COUNTIF('Test Cases'!$C$2:$C$1000,"Admin Public Content")
A21: Mitra Wisata | B21: =COUNTIF('Test Cases'!$C$2:$C$1000,"Mitra Wisata")
A22: Wisata Booking | B22: =COUNTIF('Test Cases'!$C$2:$C$1000,"Wisata Booking")
A23: Authentication | B23: =COUNTIF('Test Cases'!$C$2:$C$1000,"Authentication")
A24: Security | B24: =COUNTIF('Test Cases'!$C$2:$C$1000,"Security")
A25: Public Home | B25: =COUNTIF('Test Cases'!$C$2:$C$1000,"Public Home")
A26: Wisata Catalog | B26: =COUNTIF('Test Cases'!$C$2:$C$1000,"Wisata Catalog")
A27: Wisata Detail | B27: =COUNTIF('Test Cases'!$C$2:$C$1000,"Wisata Detail")
A28: Wisata Scan | B28: =COUNTIF('Test Cases'!$C$2:$C$1000,"Wisata Scan")
A29: User Account | B29: =COUNTIF('Test Cases'!$C$2:$C$1000,"User Account")
A30: Admin System | B30: =COUNTIF('Test Cases'!$C$2:$C$1000,"Admin System")
A31: Admin Mitra Wisata | B31: =COUNTIF('Test Cases'!$C$2:$C$1000,"Admin Mitra Wisata")
A32: Retired/Partial Modules | B32: =COUNTIF('Test Cases'!$C$2:$C$1000,"Retired/Partial Modules")
A34: Tests by Type | B34: Count
A35: Functional | B35: =COUNTIF('Test Cases'!$O$2:$O$1000,"Functional")
A36: Access Control | B36: =COUNTIF('Test Cases'!$O$2:$O$1000,"Access Control")
A37: Integration | B37: =COUNTIF('Test Cases'!$O$2:$O$1000,"Integration")
A38: Validation | B38: =COUNTIF('Test Cases'!$O$2:$O$1000,"Validation")
A39: Security | B39: =COUNTIF('Test Cases'!$O$2:$O$1000,"Security")
A40: UI | B40: =COUNTIF('Test Cases'!$O$2:$O$1000,"UI")
A41: Authentication | B41: =COUNTIF('Test Cases'!$O$2:$O$1000,"Authentication")
A42: Regression | B42: =COUNTIF('Test Cases'!$O$2:$O$1000,"Regression")
...

Sheet Route Inventory
A1: Method | B1: URI | C1: Route Name | D1: Mapped Module | E1: Expected Role | F1: Handler | G1: Middleware
A2: GET|HEAD | B2: .well-known/apple-app-site-association | D2: Other / Legacy / Shared | E2: Guest/Public | F2: App\Http\Controllers\PasskeyAssociationController@appleAppSiteAssociation | G2: web
A3: GET|HEAD | B3: .well-known/assetlinks.json | D3: Other / Legacy / Shared | E3: Guest/Public | F3: App\Http\Controllers\PasskeyAssociationController@assetLinks | G3: web
A4: GET|HEAD | B4: / | C4: home | D4: Public Web | E4: Guest/Public | F4: App\Http\Controllers\PublicHomeController@index | G4: web
A5: GET|HEAD | B5: about | C5: public.about | D5: Public Web | E5: Guest/Public | F5: App\Http\Controllers\PublicAboutController@show | G5: web
A6: GET|HEAD | B6: academy | C6: academy.search | D6: Retired Product Surface | E6: Guest/Public | F6: App\Http\Controllers\PublicAcademyController@index | G6: web
A7: POST | B7: academy/booking/confirm | C7: academy.booking.confirm | D7: Retired Product Surface | E7: Guest/Public | F7: App\Http\Controllers\AcademyPublicBookingController@confirm | G7: web, Illuminate\Auth\Middleware\Authenticate, Illuminate\Auth\Middleware\EnsureEmailIsVerified, App\Http\Middleware\EnsureUser, App\Http\Middleware\LogUserActivity, App\Http\Middleware\EnsureTransactionsAvailable
A8: POST | B8: academy/booking/prepare | C8: academy.booking.prepare | D8: Retired Product Surface | E8: Guest/Public | F8: App\Http\Controllers\AcademyPublicBookingController@prepare | G8: web, App\Http\Middleware\EnsureTransactionsAvailable
A9: GET|HEAD | B9: academy/booking/review | C9: academy.booking.review | D9: Retired Product Surface | E9: Guest/Public | F9: App\Http\Controllers\AcademyPublicBookingController@review | G9: web, Illuminate\Auth\Middleware\Authenticate, Illuminate\Auth\Middleware\EnsureEmailIsVerified, App\Http\Middleware\EnsureUser, App\Http\Middleware\LogUserActivity, App\Http\Middleware\EnsureTransactionsAvailable
A10: GET|HEAD | B10: academy/booking/{booking} | C10: academy.booking.show | D10: Retired Product Surface | E10: Guest/Public | F10: App\Http\Controllers\AcademyPublicBookingController@show | G10: web, Illuminate\Auth\Middleware\Authenticate, Illuminate\Auth\Middleware\EnsureEmailIsVerified, App\Http\Middleware\EnsureUser, App\Http\Middleware\LogUserActivity
A11: GET|HEAD | B11: academy/booking/{booking}/payment | C11: academy.booking.payment | D11: Retired Product Surface | E11: Guest/Public | F11: App\Http\Controllers\AcademyPublicBookingController@payment | G11: web, Illuminate\Auth\Middleware\Authenticate, Illuminate\Auth\Middleware\EnsureEmailIsVerified, App\Http\Middleware\EnsureUser, App\Http\Middleware\LogUserActivity, App\Http\Middleware\EnsureTransactionsAvailable
A12: GET|HEAD | B12: academy/booking/{booking}/ticket | C12: academy.booking.ticket | D12: Retired Product Surface | E12: Guest/Public | F12: App\Http\Controllers\AcademyPublicBookingController@ticket | G12: web, Illuminate\Auth\Middleware\Authenticate, Illuminate\Auth\Middleware\EnsureEmailIsVerified, App\Http\Middleware\EnsureUser, App\Http\Middleware\LogUserActivity
A13: GET|HEAD | B13: academy/{class} | C13: academy.show | D13: Retired Product Surface | E13: Guest/Public | F13: App\Http\Controllers\PublicAcademyController@show | G13: web
A14: GET|HEAD | B14: admin/academy/attendees | C14: admin.academy.attendees.index | D14: Other / Legacy / Shared | E14: Admin | F14: App\Http\Controllers\Admin\Academy\AttendeeController@index | G14: web, Illuminate\Auth\Middleware\Authenticate, Illuminate\Auth\Middleware\EnsureEmailIsVerified, App\Http\Middleware\EnsureAdmin, App\Http\Middleware\LogAdminActivity
